Traceback (most recent call last):
  File "D:\MisTrabajos\Iberdrola_Miguel\ProgramacionCuantica\venv\Lib\site-packages\jupyter_cache\executors\utils.py", line 58, in single_nb_execution
    executenb(
  File "D:\MisTrabajos\Iberdrola_Miguel\ProgramacionCuantica\venv\Lib\site-packages\nbclient\client.py", line 1305, in execute
    return NotebookClient(nb=nb, resources=resources, km=km, **kwargs).execute()
           ^^^^^^^^^^^^^^^^^^^^^^^^^^^^^^^^^^^^^^^^^^^^^^^^^^^^^^^^^^^^^^^^^^^^^
  File "D:\MisTrabajos\Iberdrola_Miguel\ProgramacionCuantica\venv\Lib\site-packages\jupyter_core\utils\__init__.py", line 173, in wrapped
    return loop.run_until_complete(inner)
           ^^^^^^^^^^^^^^^^^^^^^^^^^^^^^^
  File "D:\programas\Anaconda\Lib\asyncio\base_events.py", line 653, in run_until_complete
    return future.result()
           ^^^^^^^^^^^^^^^
  File "D:\MisTrabajos\Iberdrola_Miguel\ProgramacionCuantica\venv\Lib\site-packages\nbclient\client.py", line 705, in async_execute
    await self.async_execute_cell(
  File "D:\MisTrabajos\Iberdrola_Miguel\ProgramacionCuantica\venv\Lib\site-packages\nbclient\client.py", line 1058, in async_execute_cell
    await self._check_raise_for_error(cell, cell_index, exec_reply)
  File "D:\MisTrabajos\Iberdrola_Miguel\ProgramacionCuantica\venv\Lib\site-packages\nbclient\client.py", line 914, in _check_raise_for_error
    raise CellExecutionError.from_cell_and_msg(cell, exec_reply_content)
nbclient.exceptions.CellExecutionError: An error occurred while executing the following cell:
------------------
z.real = 4.57
------------------


[1;31m---------------------------------------------------------------------------[0m
[1;31mAttributeError[0m                            Traceback (most recent call last)
Cell [1;32mIn[23], line 1[0m
[1;32m----> 1[0m [43mz[49m[38;5;241;43m.[39;49m[43mreal[49m [38;5;241m=[39m [38;5;241m4.57[39m

[1;31mAttributeError[0m: readonly attribute

